<?xml version="1.0" encoding="UTF-8"?>
<testng-results skipped="0" failed="1" total="6" passed="5">
  <reporter-output>
  </reporter-output>
  <suite name="Default suite" duration-ms="31068" started-at="2017-02-18T19:39:58Z" finished-at="2017-02-18T19:40:29Z">
    <groups>
    </groups>
    <test name="Default test" duration-ms="31068" started-at="2017-02-18T19:39:58Z" finished-at="2017-02-18T19:40:29Z">
      <class name="com.sqa.gy.exceptions.ExceptionTest">
        <test-method status="PASS" signature="testDivisibleBy7Exception(int, int)[pri:0, instance:com.sqa.gy.exceptions.ExceptionTest@349403b0]" name="testDivisibleBy7Exception" duration-ms="4381" started-at="2017-02-18T11:39:58Z" data-provider="dp" finished-at="2017-02-18T11:40:03Z">
          <params>
            <param index="0">
              <value>
                <![CDATA[0]]>
              </value>
            </param>
            <param index="1">
              <value>
                <![CDATA[100]]>
              </value>
            </param>
          </params>
          <reporter-output>
          </reporter-output>
        </test-method> <!-- testDivisibleBy7Exception -->
        <test-method status="PASS" signature="testDivisibleBy7Exception(int, int)[pri:0, instance:com.sqa.gy.exceptions.ExceptionTest@349403b0]" name="testDivisibleBy7Exception" duration-ms="6945" started-at="2017-02-18T11:40:03Z" data-provider="dp" finished-at="2017-02-18T11:40:10Z">
          <params>
            <param index="0">
              <value>
                <![CDATA[-50]]>
              </value>
            </param>
            <param index="1">
              <value>
                <![CDATA[25]]>
              </value>
            </param>
          </params>
          <reporter-output>
          </reporter-output>
        </test-method> <!-- testDivisibleBy7Exception -->
        <test-method status="PASS" signature="testInvalidNumberException(int, int)[pri:0, instance:com.sqa.gy.exceptions.ExceptionTest@349403b0]" name="testInvalidNumberException" duration-ms="6685" started-at="2017-02-18T11:40:10Z" data-provider="dp" finished-at="2017-02-18T11:40:16Z">
          <params>
            <param index="0">
              <value>
                <![CDATA[0]]>
              </value>
            </param>
            <param index="1">
              <value>
                <![CDATA[100]]>
              </value>
            </param>
          </params>
          <reporter-output>
          </reporter-output>
        </test-method> <!-- testInvalidNumberException -->
        <test-method status="PASS" signature="testInvalidNumberException(int, int)[pri:0, instance:com.sqa.gy.exceptions.ExceptionTest@349403b0]" name="testInvalidNumberException" duration-ms="6452" started-at="2017-02-18T11:40:16Z" data-provider="dp" finished-at="2017-02-18T11:40:23Z">
          <params>
            <param index="0">
              <value>
                <![CDATA[-50]]>
              </value>
            </param>
            <param index="1">
              <value>
                <![CDATA[25]]>
              </value>
            </param>
          </params>
          <reporter-output>
          </reporter-output>
        </test-method> <!-- testInvalidNumberException -->
        <test-method status="PASS" signature="testNumberOutOfRangeException(int, int)[pri:0, instance:com.sqa.gy.exceptions.ExceptionTest@349403b0]" name="testNumberOutOfRangeException" duration-ms="5113" started-at="2017-02-18T11:40:23Z" data-provider="dp" finished-at="2017-02-18T11:40:28Z">
          <params>
            <param index="0">
              <value>
                <![CDATA[0]]>
              </value>
            </param>
            <param index="1">
              <value>
                <![CDATA[100]]>
              </value>
            </param>
          </params>
          <reporter-output>
          </reporter-output>
        </test-method> <!-- testNumberOutOfRangeException -->
        <test-method status="FAIL" signature="testNumberOutOfRangeException(int, int)[pri:0, instance:com.sqa.gy.exceptions.ExceptionTest@349403b0]" name="testNumberOutOfRangeException" duration-ms="1432" started-at="2017-02-18T11:40:28Z" data-provider="dp" finished-at="2017-02-18T11:40:29Z">
          <params>
            <param index="0">
              <value>
                <![CDATA[-50]]>
              </value>
            </param>
            <param index="1">
              <value>
                <![CDATA[25]]>
              </value>
            </param>
          </params>
          <exception class="java.lang.AssertionError">
            <message>
              <![CDATA[expected [true] but found [false]]]>
            </message>
            <full-stacktrace>
              <![CDATA[java.lang.AssertionError: expected [true] but found [false]
	at org.testng.Assert.fail(Assert.java:94)
	at org.testng.Assert.failNotEquals(Assert.java:513)
	at org.testng.Assert.assertEqualsImpl(Assert.java:135)
	at org.testng.Assert.assertEquals(Assert.java:116)
	at org.testng.Assert.assertEquals(Assert.java:305)
	at org.testng.Assert.assertEquals(Assert.java:315)
	at com.sqa.gy.exceptions.ExceptionTest.testNumberOutOfRangeException(ExceptionTest.java:57)
	at sun.reflect.NativeMethodAccessorImpl.invoke0(Native Method)
	at sun.reflect.NativeMethodAccessorImpl.invoke(NativeMethodAccessorImpl.java:57)
	at sun.reflect.DelegatingMethodAccessorImpl.invoke(DelegatingMethodAccessorImpl.java:43)
	at java.lang.reflect.Method.invoke(Method.java:606)
	at org.testng.internal.MethodInvocationHelper.invokeMethod(MethodInvocationHelper.java:86)
	at org.testng.internal.Invoker.invokeMethod(Invoker.java:643)
	at org.testng.internal.Invoker.invokeTestMethod(Invoker.java:820)
	at org.testng.internal.Invoker.invokeTestMethods(Invoker.java:1128)
	at org.testng.internal.TestMethodWorker.invokeTestMethods(TestMethodWorker.java:129)
	at org.testng.internal.TestMethodWorker.run(TestMethodWorker.java:112)
	at org.testng.TestRunner.privateRun(TestRunner.java:782)
	at org.testng.TestRunner.run(TestRunner.java:632)
	at org.testng.SuiteRunner.runTest(SuiteRunner.java:366)
	at org.testng.SuiteRunner.runSequentially(SuiteRunner.java:361)
	at org.testng.SuiteRunner.privateRun(SuiteRunner.java:319)
	at org.testng.SuiteRunner.run(SuiteRunner.java:268)
	at org.testng.SuiteRunnerWorker.runSuite(SuiteRunnerWorker.java:52)
	at org.testng.SuiteRunnerWorker.run(SuiteRunnerWorker.java:86)
	at org.testng.TestNG.runSuitesSequentially(TestNG.java:1244)
	at org.testng.TestNG.runSuitesLocally(TestNG.java:1169)
	at org.testng.TestNG.run(TestNG.java:1064)
	at org.testng.remote.AbstractRemoteTestNG.run(AbstractRemoteTestNG.java:132)
	at org.testng.remote.RemoteTestNG.initAndRun(RemoteTestNG.java:236)
	at org.testng.remote.RemoteTestNG.main(RemoteTestNG.java:81)
]]>
            </full-stacktrace>
          </exception> <!-- java.lang.AssertionError -->
          <reporter-output>
          </reporter-output>
        </test-method> <!-- testNumberOutOfRangeException -->
      </class> <!-- com.sqa.gy.exceptions.ExceptionTest -->
    </test> <!-- Default test -->
  </suite> <!-- Default suite -->
</testng-results>
